Workbook

Sheet SUMMARY - TEST
B2: SUMMARY TEST (NAMA APLIKASI) PROJECT
B3: QA TESTER : | C3: QA TRAINING - NEW MEMBER | J3: TEST VALIDATOR : | K3: TRAINER SOFTWARE QUALITY
C4: QA TRAINING - NEW MEMBER
B5: TEST | C5: TOTAL MODUL / API / FUNCTION | D5: TOTAL TEST-CASE | E5: TESTED | F5: UNTESTED | G5: BUG | J5: SUMMARY | K5: TEST PERCENTAGE | L5: BUG PERCENTAGE
B6: UI | C6: ='UI-TEST'!C10 -> 3 | D6: ='UI-TEST'!H10 -> 14 | E6: ='UI-TEST'!H8 -> 0 | F6: =(D6-E6) -> 14 | G6: ='UI-TEST'!C9 -> #REF! | J6: UI TEST | K6: =(E6/D6)*100% -> 0
J7: UI TEST BUG | L7: =(G6/D6)*100% -> #REF!
B8: INTEGRATION | C8: ='INTEGRATION-TEST'!C10 -> 35 | D8: ='INTEGRATION-TEST'!K10 -> 35 | E8: ='INTEGRATION-TEST'!K8 -> 35 | F8: =(D8-E8) -> 0 | G8: ='INTEGRATION-TEST'!C9 -> 0 | J8: INTEGRATION TEST | K8: =(E8/D8)*100% -> 1
J9: INTEGRATION TEST BUG | L9: =(G8/D8)*100% -> 0
B10: UNIT | C10: ='UNIT-TEST'!C10 -> 7 | D10: ='UNIT-TEST'!G10 -> 12 | E10: ='UNIT-TEST'!G8 -> 6 | F10: =(D10-E10) -> 6 | G10: ='UNIT-TEST'!C9 -> 1 | J10: UNIT TEST | K10: =(E10/D10)*100% -> 0.5
J11: UNIT TEST BUG | L11: =(G10/D10)*100% -> 0.083333333

Sheet BUG REPORT
C3: UI TEST BUG FORM | R3: INTEGRATION TEST BUG FORM | AG3: UNIT TEST BUG FORM
C4: PROJECT NAME : | L4: BUG FIXING | R4: PROJECT NAME : | AA4: BUG FIXING | AG4: PROJECT NAME : | AP4: BUG FIXING
C6: ENVIRONMENT | D6: SCENARIO ID | E6: MODULE / SERVICE | F6: ISSUE LINK | G6: BUG DESCRIPTION | H6: TEST STEP | I6: SEVERITY | J6: BUG FOUND BY | K6: BUG FOUND DATE | L6: ASSIGNED BY | M6: ASSIGNED TO | N6: STATUS | O6: EVIDENCE | R6: ENVIRONMENT | S6: SENARIO ID | T6: API NAME | U6: ISSUE LINK | V6: BUG DESCRIPTION | W6: TEST STEP | X6: SEVERITY | Y6: BUG FOUND BY | Z6: BUG FOUND DATE | AA6: ASSIGNED BY | AB6: ASSIGNED TO | AC6: STATUS | AD6: EVIDENCE | AG6: ENVIRONMENT | AH6: SENARIO ID | AI6: FUNCTION | AJ6: ISSUE LINK | AK6: BUG DESCRIPTION | AL6: TEST STEP | AM6: SEVERITY | AN6: BUG FOUND BY | AO6: BUG FOUND DATE | AP6: ASSIGNED BY | AQ6: ASSIGNED TO | AR6: STATUS | AS6: EVIDENCE
C7: DEVELOPMENT | D7: TS-UI-BBBB-002 | E7: MODULE-CCC | G7: TIDAK SESUAI | H7: 1.2.3.4.5. | I7: HIGH | J7: QA-1 | K7: 30-05-2024 | L7: PM | M7: PROGRAMMER-01 | N7: INPROGRESS | O7: ISSUE COMMENT LINK | R7: PRODUCTION | S7: TS-UI-CCC-001 | T7: API SUBMIT | V7: TIDAK SESUAI | W7: 1.2.3.4.5. | X7: HIGH | Y7: QA-1 | Z7: 30-05-2024 | AA7: PM | AB7: PROGRAMMER-01 | AC7: INPROGRESS | AD7: ISSUE COMMENT LINK | AG7: PRODUCTION | AH7: TS-UI-CCC-001 | AI7: SUBMIT FUNCTION | AK7: TIDAK SESUAI | AL7: 1.2.3.4.5. | AM7: HIGH | AN7: QA-1 | AO7: 30-05-2024 | AP7: PM | AQ7: PROGRAMMER-01 | AR7: INPROGRESS | AS7: ISSUE COMMENT LINK

Sheet UI-TEST
B2: TEST CASE TESTING UI : CYPRESS
B6: Project : | C6: SAUCE DEMO | J6: TOTAL DEV TEST PRESENTATION | K6: Gambar | T6: DEV RELEASE STATUS | V6: RE-TEST ENVIRONTMENT PRODUCTION FIELD
B7: Environment : | C7: PROD | V7: Environment : | W7: STAGING/ PRODUCTION | X7: TEST PRESENTATION | Z7: Total Test | AA7: 100 | AB7: PROD RELEASE STATUS
B8: Test Berhasil : | C8: =COUNTIF(OFFSET(L15, 0, 0, COUNTA(L:L) - COUNTA(L$1:L$14)), "PASS") + COUNTIF(OFFSET(L15, 0, 0, COUNTA(L:L) - COUNTA(L$1:L$14)), "PASS WITH NOTE") -> #REF! | G8: Sudah Di Test : | H8: =COUNTA(L15:INDEX(L:L, ROWS(L:L))) -> 0 | Z8: Sudah Di Test | AA8: 20
B9: Test Gagal : | C9: =COUNTIF(OFFSET(L15, 0, 0, COUNTA(L:L) - COUNTA(L$1:L$14)), "FAILED") -> #REF! | G9: Belum Di Test : | H9: =(H10-H8) -> 14 | J9: =(H8/H10)*100% -> 0 | T9: RELEASE | Z9: Belum Di Test | AB9: RELEASE
B10: Total Modul : | C10: =COUNTA(C15:INDEX(C:C, ROWS(C:C))) -> 3 | G10: Total Test Case : | H10: =COUNTA(B15:INDEX(B:B, ROWS(B:B))) -> 14 | Z10: Test Gagal
Z11: Persentase | AA11: =(AA8/AA7)*100% -> 0.2
B14: SCENARIO ID | C14: Module / Service | D14: Test Scenario | E14: Page | F14: Test Case | G14: Test Type | H14: Data | I14: Test Step | J14: Expected Result | K14: Actual Result | L14: Status | M14: Test Date | N14: QA DEV Note | O14: Severity | P14: Tested By | Q14: Link Issue | R14: Branch Name | S14: File name | T14: Evidence | V14: Re-Tested By | W14: Re-Tested Date | X14: Status | Y14: QA MSOS Note | Z14: Branch Name | AA14: Link Issue | AB14: Evidence
B15: TS-UI-Login-001 | C15: LOGIN | D15: Login berhasil | E15: Login | F15: Melakukan login menggunakan username dan password benar | G15: Positif | H15: Username : standard_user Password : secret_sauce | I15: 1. User mengunjungi halaman login 2. User memasukan username dan password 3. User melakukan klik button login 4. User berhasil login | J15: Berhasil Login
B16: TS-UI-Login-002 | D16: Login gagal | E16: Login | F16: Melakukan login menggunakan username salah dan password benar | G16: Negatif | H16: Username : coba Password : secret_sauce | I16: 1. User mengunjungi halaman login 2. User memasukan username dan password 3. User melakukan klik button login 4. Muncul notifikasi username atau password salah | J16: Muncul notifikasi : Username and password do not match any user in this service
B17: TS-UI-Login-003 | D17: Login gagal | E17: Login | F17: Melakukan login menggunakan username benar dan password salah | G17: Negatif | H17: Username : standard_user Password : salah | I17: 1. User mengunjungi halaman login 2. User memasukan username dan password 3. User melakukan klik button login 4. Muncul notifikasi username atau password salah | J17: Muncul notifikasi : Username and password do not match any user in this service
B18: TS-UI-Login-004 | D18: Login gagal | E18: Login | F18: Melakukan login menggunakan username yang terkunci dan password benar | G18: Negatif | H18: Username : locked_out_user Password : secret_sauce | I18: 1. User mengunjungi halaman login 2. User memasukan username dan password 3. User melakukan klik button login 4. Muncul notifikasi user locked | J18: Muncul notifikasi : Sorry, this user has been locked out.
B19: TS-UI-Dashboard-001 | C19: Dashboard | D19: Filter barang | E19: All item | F19: Melakukan filter barang berdasarkan abjad dari A ke Z | G19: Positif | H19: - | I19: 1. User mengunjungi halaman dashboard 2. User melakukan filter barang dari A ke Z 3. Berhasil menampilkan barang | J19: Menampilkan urutan barang dari abjad A ke Z
B20: TS-UI-Dashboard-002 | D20: Filter barang | E20: All item | F20: Melakukan filter barang berdasarkan abjad dari Z ke A | G20: Positif | H20: - | I20: 1. User mengunjungi halaman dashboard 2. User melakukan filter barang dari Z ke A 3. Berhasil menampilkan barang | J20: Menampilkan urutan barang dari abjad Z ke A
B21: TS-UI-Dashboard-003 | D21: Filter barang | E21: All item | F21: Melakukan filter barang berdasarkan harga dari low ke high | G21: Positif | H21: - | I21: 1. User mengunjungi halaman dashboard 2. User melakukan filter barang dari low ke high 3. Berhasil menampilkan barang | J21: Menampilkan barang dari harga terendah ke terbesar
B22: TS-UI-Dashboard-004 | D22: Filter barang | E22: All item | F22: Melakukan filter barang berdasarkan harga dari high ke low | G22: Positif | H22: - | I22: 1. User mengunjungi halaman dashboard 2. User melakukan filter barang dari high ke low 3. Berhasil menampilkan barang | J22: Menampilkan barang dari harga terbesaar ke terendah
B23: TS-UI-CART-001 | C23: Cart | D23: Menambahkan 1 barang ke kranjang | E23: All item | F23: user melakukan tambah 1 barang ke keranjang | G23: Positif | H23: - | I23: 1. user mengunjungi halaman all items 2. user menambahkan salah satu barang ke keranjang 3. berhasil menambahkan barang | J23: Berhasil menambahkan 1 barang ke keranjang
B24: TS-UI-CART-002 | D24: Menghapus 1 barang dari keranjang | E24: All item | F24: user melakukan hapus 1 barang dari keranjang | G24: Positif | H24: - | I24: 1. user mengunjungi halaman all items 2. user melakukan klik pada icon keranjang 3. user melakukan klik pada button remove 4. berhasil menghapus barang | J24: Berhasil menghapus 1 barang dari keranjang
B25: TS-UI-CART-003 | D25: Menambahkan 2 barang ke kranjang | E25: All item | F25: user melakukan tambah 2 barang ke keranjang | G25: Positif | H25: - | I25: 1. user mengunjungi halaman all items 2. user menambahkan 2 barang ke keranjang 3. berhasil menambahkan barang | J25: Berhasil menambahkan 2 barang ke keranjang
B26: TS-UI-CART-004 | D26: Menghapus 2 barang dari keranjang | E26: All item | F26: user melakukan hapus 2 barang dari keranjang | G26: Positif | H26: - | I26: 1. user mengunjungi halaman all items 2. user melakukan klik pada icon keranjang 3. user melakukan klik pada button remove 4. berhasil menghapus barang | J26: Berhasil menghapus 2 barang dari keranjang
B27: TS-UI-CART-005 | D27: Menambahkan barang dari menu keranjang | E27: All item | F27: user melakukan tambah 1 barang dari menu all item, kemudian masuk ke icon keranjang kemudian menambahkan 1 barang lagi | G27: Positif | H27: - | I27: 1. user mengunjungi halaman all items 2. user menambahkan satu barang ke keranjang 3. user melakukan klik pada button continue shopping 4. user menambahkan satu barang ke keranjang 5. barang berhasil di tambahkan | J27: berhasil menambahkan barang
B28: TS-UI-CART-006 | D28: Checkout barang | E28: All item | F28: User melakukan checkout barang | G28: Positif | H28: first name : ayu last name : dian zip / postal code : 45234 | I28: 1. user mengunjungi halaman all itemes 2. user menambahkan satu barang ke keranjang 3. user melakukan klik pada icon keranjang 4. user melakukan klik pada button checkout 5. user menginputkan data 6. user melakukan klik pada button continue 7. user melakukan klik pada button finish | J28: Berhasil checkut barang

Sheet |OPS|UI TEST - EXISTING FEATURE
B2: TEST CASE EXISTING TEST UI : CYPRESS
B6: Project : | C6: NAMA APLIKASI | I6: EXISTING TEST PRESENTATION | Q6: DEV RELEASE STATUS | S6: RE-TEST ENVIRONTMENT PRODUCTION FIELD
B7: Environment : | C7: DEVELOPMENT | S7: Environment : | T7: STAGING/ PRODUCTION | V7: TEST PRESENTATION | X7: RELEASE STATUS
B8: Branch : | C8: TestingApp | F8: Sudah Di Test : | G8: 29
B9: Test Berhasil : | C9: 27 | F9: Belum Di Test : | G9: 0 | I9: 1 | Q9: RELEASE | S9: Branch Name Test : | X9: RELEASE
B10: Test Gagal : | C10: 2 | F10: Total Test Case : | G10: 29
B14: Branch : | S14: Branch : | W14: Total Test | X14: 100
B15: Modul / Service : | W15: Sudah Di Test | X15: 20
F16: Sudah Di Test : | G16: 12 | S16: Modul / Service : | W16: Belum Di Test
B17: Test Berhasil : | C17: 12 | F17: Belum Di Test : | G17: 0 | W17: Test Gagal
B18: Test Gagal : | C18: 0 | F18: Total Test Case : | G18: 12 | W18: Persentase | X18: =(X15/X14)*100% -> 0.2
B19: SCENARIO ID | C19: Test Scenario | D19: Page | E19: Test Case | F19: Test Type | G19: Data | H19: Test Step | I19: Expected Result | J19: Actual Result | K19: Status | L19: Test Date | M19: QA Note | N19: Severity | O19: Tested By | P19: Link Issue | Q19: Evidence | S19: Re-Tested By | T19: RE-TEST DATE | U19: Status | V19: QA MSOS Note | W19: Link Issue | X19: Evidence
B80: Modul / Service
B81: Branch : | S81: Branch : | W81: Total Test | X81: 100
B82: Modul / Service | W82: Sudah Di Test | X82: 20
F83: Sudah Di Test : | G83: 12 | S83: Modul / Service : | W83: Belum Di Test
B84: Test Berhasil : | C84: 12 | F84: Belum Di Test : | G84: 0 | W84: Test Gagal
B85: Test Gagal : | C85: 0 | F85: Total Test Case : | G85: 12 | W85: Persentase | X85: =(X82/X81)*100% -> 0.2
B86: SCENARIO ID | C86: Test Scenario | D86: Page | E86: Test Case | F86: Test Type | G86: Data | H86: Test Step | I86: Expected Result | J86: Actual Result | K86: Status | L86: Test Date | M86: QA Note | N86: Severity | O86: Tested By | P86: Link Issue | Q86: Evidence | S86: Re-Tested By | T86: RE-TEST DATE | U86: Status | V86: QA MSOS Note | W86: Link Issue | X86: Evidence

Sheet INTEGRATION-TEST
B2: TEST CASE INTEGRATION TEST : API TEST (POSTMAN)
B6: Project : | C6: TESTING API TRAINING | L6: Total Presentase Test | Q6: LABLE STATUS
B7: Environtment : | C7: PRODUCTION
B8: Total Test Berhasil : | C8: =COUNTIF(OFFSET(K14, 0, 0, COUNTA(K:K) - COUNTA(K$1:K$13)), "PASS") + COUNTIF(OFFSET(K14, 0, 0, COUNTA(K:K) - COUNTA(K$1:K$13)), "PASS WITH NOTE") -> 35 | J8: Total Sudah Di Test : | K8: =COUNTA(K14:INDEX(K:K, ROWS(K:K))) -> 35
B9: Total Test Gagal : | C9: =COUNTIF(OFFSET(K14, 0, 0, COUNTA(K:K) - COUNTA(K$1:K$13)), "FAILED") -> 0 | J9: Total Belum Di Test : | K9: =(K10-K8) -> 0 | L9: =(K8/K10)*100% -> 1 | Q9: RELEASE BY QA
B10: Total API : | C10: =COUNTA(B14:INDEX(B:B, ROWS(B:B))) -> 35 | J10: Total Test Case : | K10: =COUNTA(B14:INDEX(B:B, ROWS(B:B))) -> 35
B13: Scenario ID | C13: API Name | D13: Collection Name | E13: API URL | F13: Test Type | G13: Test Step | H13: Expected Response | I13: Actual Response | J13: Status Response | K13: Status | L13: Test Date | M13: QA Note | N13: Severity | O13: Link Issue | P13: Tested By | Q13: Evidence
B14: IT-PRODUCTS-001 | C14: Get All Products | D14: PRODUCTS | E14: https://api.escuelajs.co/api/v1/products/ | F14: Positif | G14: cukup memasukan url saja tanpa request (METHOD : GET) | H14: Menampilkan semua data produk | I14: Expexted | J14: 200 | K14: PASS | L14: 45698 | O14: https://git.neuron.id/ui-testing/qa-training-project/-/issues/3 | P14: Fikri Wilya Pratama
B15: IT-PRODUCTS-002 | C15: Get All Products By Id | E15: https://api.escuelajs.co/api/v1/products/{id} | F15: Positif | G15: (METHOD : GET) cukup memasukan url saja tanpa request, parameter {id} di diganti dengan id yang didapatkan dari api get all product | H15: Menampilkan data produk berdasarkan id | I15: Expexted | J15: 200 | K15: PASS | L15: 45698 | O15: https://git.neuron.id/ui-testing/qa-training-project/-/issues/4 | P15: Fikri Wilya Pratama
B16: IT-PRODUCTS-003 | F16: Negatif | G16: (METHOD : GET) cukup memasukan url saja tanpa request, parameter {id} di diganti dengan id yang tidak ada di api get all product | H16: Menampilkan message : Could not find any entity of type | I16: Expexted | J16: 200 | K16: PASS | L16: 45698 | O16: https://git.neuron.id/ui-testing/qa-training-project/-/issues/5 | P16: Fikri Wilya Pratama
B17: IT-PRODUCTS-004 | C17: Add Products | E17: https://api.escuelajs.co/api/v1/products/ | F17: Positif | G17: (METHOD : POST) 1. masukan url 2. pilih body kemudian klik raw 3. masukan request (contoh request dapat dilihat di https://api.escuelajs.co/docs#/) 4. send | H17: Menampilkan data produk yang berhasil ditambahkan | I17: Expexted | J17: 200 | K17: PASS | L17: 2/10/2025 | O17: https://git.neuron.id/ui-testing/qa-training-project/-/issues/6 | P17: Fikri Wilya Pratama
B18: IT-PRODUCTS-005 | F18: Negatif | G18: (METHOD : POST) 1. masukan url 2. pilih body kemudian klik raw 3. masukan request (contoh request dapat dilihat di https://api.escuelajs.co/docs#/) 4. salah satu variable tipe datanya dirubah ke int 5. send | H18: Menampilkan error : Bad Request | I18: Expexted | J18: 400 | K18: PASS | L18: 2/10/2025 | O18: https://git.neuron.id/ui-testing/qa-training-project/-/issues/7 | P18: Fikri Wilya Pratama
B19: IT-PRODUCTS-006 | C19: Update Products By Id | E19: https://api.escuelajs.co/api/v1/products/ | F19: Positif | G19: (METHOD : PUT) 1. masukan url 2. parameter {id} di diganti dengan id yang didapatkan dari api get all product 3. pilih body kemudian klik raw 4. masukan request (contoh request dapat dilihat di https://api.escuelajs.co/docs#/) 5. salah satu variable dirubah value nya 6. send | H19: Menampilkan data produk berdasarkan id dan value variable nya berhasil berubah | I19: Expexted | J19: 200 | K19: PASS | L19: 2/10/2025 | O19: https://git.neuron.id/ui-testing/qa-training-project/-/issues/8 | P19: Fikri Wilya Pratama
B20: IT-PRODUCTS-007 | F20: Negatif | G20: (METHOD : PUT) 1. masukan url 2. parameter {id} di diganti dengan id yang tidak ada di api get all product 3. pilih body kemudian klik raw 4. masukan request (contoh request dapat dilihat di https://api.escuelajs.co/docs#/) 5. send | H20: Menampilkan message : Could not find any entity of type | I20: Expexted | J20: 400 | K20: PASS | L20: 2/10/2025 | O20: https://git.neuron.id/ui-testing/qa-training-project/-/issues/9 | P20: Fikri Wilya Pratama
B21: IT-USERS-001 | C21: Get All Users | D21: USERS | E21: https://api.escuelajs.co/api/v1/users/ | F21: Positif | G21: (METHOD : GET) cukup memasukan url saja tanpa request | H21: Menampilkan semua data user | I21: Expexted | J21: 200 | K21: PASS | L21: 2/10/2025 | O21: https://git.neuron.id/ui-testing/qa-training-project/-/issues/10 | P21: Fikri Wilya Pratama
B22: IT-USERS-002 | C22: Get All Users By Id | E22: https://api.escuelajs.co/api/v1/users/{id} | F22: Positif | G22: (METHOD : GET) cukup memasukan url saja tanpa request, parameter {id} di diganti dengan id yang didapatkan dari api get all users | H22: Menampilkan data user berdasarkan id | I22: Expexted | J22: 200 | K22: PASS | L22: 45698 | O22: https://git.neuron.id/ui-testing/qa-training-project/-/issues/11 | P22: Fikri Wilya Pratama
B23: IT-USERS-003 | F23: Negatif | G23: (METHOD : GET) cukup memasukan url saja tanpa request, parameter {id} di diganti dengan id yang tidak ada di api get all users | H23: Menampilkan message : Could not find any entity of type | I23: Expexted | J23: 400 | K23: PASS | L23: 45698 | O23: https://git.neuron.id/ui-testing/qa-training-project/-/issues/12 | P23: Fikri Wilya Pratama
B24: IT-USERS-004 | C24: Update User By Id | F24: Positif | G24: (METHOD : PUT) 1. masukan url 2. parameter {id} di diganti dengan id yang didapatkan dari api add users 3. pilih body kemudian klik raw 4. masukan request (contoh request dapat dilihat di https://api.escuelajs.co/docs#/) 5. salah satu variable dirubah value nya 6. send | H24: Menampilkan data user berdasarkan id dan value variable nya berhasil berubah | I24: Expexted | J24: 200 | K24: PASS | L24: 45698 | O24: https://git.neuron.id/ui-testing/qa-training-project/-/issues/13 | P24: Fikri Wilya Pratama
B25: IT-USERS-005 | F25: Negatif | G25: (METHOD : PUT) 1. masukan url 2. parameter {id} di diganti dengan id yang tidak ada di api get all users 3. pilih body kemudian klik raw 4. masukan request (contoh request dapat dilihat di https://api.escuelajs.co/docs#/) 5. send | H25: Menampilkan message : Could not find any entity of type | I25: Expexted | J25: 400 | K25: PASS | L25: 2/10/2025 | O25: https://git.neuron.id/ui-testing/qa-training-project/-/issues/14 | P25: Fikri Wilya Pratama
B26: IT-USERS-006 | C26: Delete User By Id | F26: Positif | G26: (METHOD : DELETE) cukup memasukan url saja tanpa request, parameter {id} di diganti dengan id yang didapatkan dari api get all users | H26: Menampilkan response : true | I26: Expexted | J26: 200 | K26: PASS | L26: 2/10/2025 | O26: https://git.neuron.id/ui-testing/qa-training-project/-/issues/15 | P26: Fikri Wilya Pratama
B27: IT-USERS-007 | F27: Negatif | G27: (METHOD : DELETE) cukup memasukan url saja tanpa request, parameter {id} di diganti dengan id yang tidak ada di api get all users | H27: Menampilkan message : Could not find any entity of type | I27: Expexted | J27: 400 | K27: PASS | L27: 2/10/2025 | O27: https://git.neuron.id/ui-testing/qa-training-project/-/issues/16 | P27: Fikri Wilya Pratama
B28: IT-USERS-008 | C28: Add Users | E28: https://api.escuelajs.co/api/v1/users/ | F28: Positif | G28: (METHOD : POST) 1. masukan url 2. pilih body kemudian klik raw 3. masukan request (contoh request dapat dilihat di https://api.escuelajs.co/docs#/) 4. send | H28: Menampilkan data user yang berhasil ditambahkan | I28: Expexted | J28: 201 | K28: PASS | L28: 2/10/2025 | O28: https://git.neuron.id/ui-testing/qa-training-project/-/issues/17 | P28: Fikri Wilya Pratama
B29: IT-USERS-009 | F29: Negatif | G29: (METHOD : POST) 1. masukan url 2. pilih body kemudian klik raw 3. masukan request (contoh request dapat dilihat di https://api.escuelajs.co/docs#/) 4. salah satu variable dirubah tipe datanya ke int 4. send | H29: Menampilkan error : Bad Request | I29: Expexted | J29: 400 | K29: PASS | L29: 2/10/2025 | O29: https://git.neuron.id/ui-testing/qa-training-project/-/issues/18 | P29: Fikri Wilya Pratama
B30: IT-AUTH-001 | C30: Login | D30: AUTH | E30: https://api.escuelajs.co/api/v1/auth/login | F30: Positif | G30: (METHOD : POST) 1. masukan url 2. pilih body kemudian klik raw 3. masukan request (contoh request dapat dilihat di https://api.escuelajs.co/docs#/) variable username dan password 4. value username dan password didapatkan dari api get all users 4. send | H30: Menampilkan response access_token dan refresh_token | I30: Expexted | J30: 201 | K30: PASS | L30: 2/10/2025 | O30: https://git.neuron.id/ui-testing/qa-training-project/-/issues/19 | P30: Fikri Wilya Pratama
B31: IT-AUTH-002 | F31: Negatif | G31: (METHOD : POST) 1. masukan url 2. pilih body kemudian klik raw 3. masukan request (contoh request dapat dilihat di https://api.escuelajs.co/docs#/) variable username dan password 4. salah satu variable di isi dengan value false 4. send | H31: Menampilkan message : Unauthorized | I31: Expexted | J31: 401 | K31: PASS | L31: 2/10/2025 | O31: https://git.neuron.id/ui-testing/qa-training-project/-/issues/20 | P31: Fikri Wilya Pratama
B32: IT-AUTH-003 | C32: Get Profile | E32: https://api.escuelajs.co/api/v1/auth/profile | F32: Positif | G32: (METHOD : GET) 1. masukan url 2. pilih Authorization 3. pilih Auth Type Bearer Token 4. masukan token yang di dapatkan dari api login, token yang di inputkan yaitu dari variable access_token 4. send | H32: Menampilkan data users | I32: Expexted | J32: 200 | K32: PASS | L32: 45698 | O32: https://git.neuron.id/ui-testing/qa-training-project/-/issues/21 | P32: Fikri Wilya Pratama
B33: IT-AUTH-004 | F33: Negatif | G33: (METHOD : GET) 1. masukan url 2. pilih Authorization 3. pilih Auth Type Bearer Token 4. masukan token yang salah 4. send | H33: Menampilkan message : Unauthorized | I33: Expexted | J33: 401 | K33: PASS | L33: 45698 | O33: https://git.neuron.id/ui-testing/qa-training-project/-/issues/22 | P33: Fikri Wilya Pratama
B34: IT-CATEGORIES-001 | C34: Get All Categories | D34: CATEGORIES | E34: https://api.escuelajs.co/api/v1/categories/ | F34: Positif | G34: (METHOD : GET) cukup memasukan url saja tanpa request | H34: Menampilkan semua data kategori | I34: Expexted | J34: 200 | K34: PASS | L34: 45698 | O34: https://git.neuron.id/ui-testing/qa-training-project/-/issues/23 | P34: Fikri Wilya Pratama
B35: IT-CATEGORIES-002 | C35: Get Categories By Id | E35: https://api.escuelajs.co/api/v1/categories/{id} | F35: Positif | G35: (METHOD : GET) cukup memasukan url saja tanpa request, parameter {id} di diganti dengan id yang didapatkan dari api get all categories | H35: Menampilkan data kategori berdasarkan id | I35: Expexted | J35: 200 | K35: PASS | L35: 2/10/2025 | O35: https://git.neuron.id/ui-testing/qa-training-project/-/issues/24 | P35: Fikri Wilya Pratama
B36: IT-CATEGORIES-003 | F36: Negatif | G36: (METHOD : GET) cukup memasukan url saja tanpa request, parameter {id} di diganti dengan id yang tidak ada di api get all categories | H36: Menampilkan message : Could not find any entity of type | I36: Expexted | J36: 400 | K36: PASS | L36: 2/10/2025 | O36: https://git.neuron.id/ui-testing/qa-training-project/-/issues/25 | P36: Fikri Wilya Pratama
B37: IT-CATEGORIES-004 | C37: Get Products By Id Categories | E37: https://api.escuelajs.co/api/v1/categories/{id}/products | F37: Positif | G37: (METHOD : GET) cukup memasukan url saja tanpa request, parameter {id} di diganti dengan id yang didapatkan dari api get all categories | H37: Menampilkan data produk berdasarkan id kategori | I37: Expexted | J37: 200 | K37: PASS | L37: 2/10/2025 | O37: https://git.neuron.id/ui-testing/qa-training-project/-/issues/26 | P37: Fikri Wilya Pratama
B38: IT-CATEGORIES-005 | F38: Negatif | G38: (METHOD : GET) cukup memasukan url saja tanpa request, parameter {id} di diganti dengan id yang tidak ada di api get all categories | H38: Menampilkan response : [] | I38: Expexted | J38: 200 | K38: PASS | L38: 2/10/2025 | O38: https://git.neuron.id/ui-testing/qa-training-project/-/issues/27 | P38: Fikri Wilya Pratama
B39: IT-CATEGORIES-006 | C39: Update Categories By Id | E39: https://api.escuelajs.co/api/v1/categories/{id} | F39: Positif | G39: (METHOD : PUT) 1. masukan url 2. parameter {id} di diganti dengan id yang didapatkan dari api get all categories 3. pilih body kemudian klik raw 4. masukan request (contoh request dapat dilihat di https://api.escuelajs.co/docs#/) 5. salah satu variable dirubah value nya 6. send | H39: Menampilkan data kategori berdasarkan id dan value variable nya berhasil berubah | I39: Expexted | J39: 200 | K39: PASS | L39: 2/10/2025 | O39: https://git.neuron.id/ui-testing/qa-training-project/-/issues/28 | P39: Fikri Wilya Pratama
B40: IT-CATEGORIES-007 | F40: Negatif | G40: (METHOD : PUT) 1. masukan url 2. parameter {id} di diganti dengan id yang tidak ada di api get all categories 3. pilih body kemudian klik raw 4. masukan request (contoh request dapat dilihat di https://api.escuelajs.co/docs#/) 5. send | H40: Menampilkan message : Could not find any entity of type | I40: Expexted | J40: 400 | K40: PASS | L40: 45698 | O40: https://git.neuron.id/ui-testing/qa-training-project/-/issues/29 | P40: Fikri Wilya Pratama
B41: IT-CATEGORIES-008 | C41: Add Categories | E41: https://api.escuelajs.co/api/v1/categories/ | F41: Positif | G41: (METHOD : POST) 1. masukan url 2. pilih body kemudian klik raw 3. masukan request (contoh request dapat dilihat di https://api.escuelajs.co/docs#/) 4. send | H41: Menampilkan data categories yang berhasil ditambahkan | I41: Expexted | J41: 201 | K41: PASS | L41: 45698 | O41: https://git.neuron.id/ui-testing/qa-training-project/-/issues/30 | P41: Fikri Wilya Pratama
B42: IT-CATEGORIES-009 | F42: Negatif | G42: (METHOD : POST) 1. masukan url 2. pilih body kemudian klik raw 3. masukan request (contoh request dapat dilihat di https://api.escuelajs.co/docs#/) 4. salah satu variable request dirubah tipe data ke int 4. send | H42: Menampilkan error : Bad Request | I42: Expexted | J42: 400 | K42: PASS | L42: 45698 | O42: https://git.neuron.id/ui-testing/qa-training-project/-/issues/31 | P42: Fikri Wilya Pratama
B43: IT-CATEGORIES-010 | C43: Delete Categories | E43: https://api.escuelajs.co/api/v1/categories/{id} | F43: Positif | G43: (METHOD : DELETE) cukup memasukan url saja tanpa request, parameter {id} di diganti dengan id yang didapatkan dari api get all categories | H43: Menampilkan response : true | I43: Expexted | J43: 200 | K43: PASS | L43: 2/10/2025 | O43: https://git.neuron.id/ui-testing/qa-training-project/-/issues/32 | P43: Fikri Wilya Pratama
B44: IT-CATEGORIES-011 | F44: Negatif | G44: (METHOD : DELETE) cukup memasukan url saja tanpa request, parameter {id} di diganti dengan id yang tidak ada di api get all categories | H44: Menampilkan message : Could not find any entity of type | I44: Expexted | J44: 400 | K44: PASS | L44: 2/10/2025 | O44: https://git.neuron.id/ui-testing/qa-training-project/-/issues/33 | P44: Fikri Wilya Pratama
B45: IT-FILES-001 | C45: Upload | D45: Files | E45: https://api.escuelajs.co/api/v1/files/upload | F45: Positif | G45: (METHOD : POST) 1. masukan url 2. pilih body kemudian klik form-data 3. isi kolom key dengan "file" tanpa tanda kutip 4. rubah type text menjadi type file 4. pada kolom value diklik kemudian upload gambar dari local 5. send | H45: Menampilkan data file yang berhasil diupload | I45: Expexted | J45: 201 | K45: PASS | L45: 2/10/2025 | O45: https://git.neuron.id/ui-testing/qa-training-project/-/issues/34 | P45: Fikri Wilya Pratama
B46: IT-FILES-002 | F46: Negatif | G46: (METHOD : POST) 1. masukan url 2. pilih body kemudian klik form-data 3. isi kolom key dengan "file" tanpa tanda kutip 4. rubah type text menjadi type file 4. pada kolom value dikosongkan 5. send | H46: Menampilkan message : Internal Server Error | I46: Expexted | J46: 500 | K46: PASS | L46: 45698 | O46: https://git.neuron.id/ui-testing/qa-training-project/-/issues/35 | P46: Fikri Wilya Pratama
...

Sheet UNIT-TEST
B2: TEST CASE TESTING UNIT : PHPUNIT
B6: Project : | H6: Total Presentase Test | O6: LABLE STATUS
B7: Environment :
B8: Test Berhasil : | C8: =COUNTIF(OFFSET(I14, 0, 0, COUNTA(I:I) - COUNTA(I$1:I$13)), "PASS") + COUNTIF(OFFSET(I14, 0, 0, COUNTA(I:I) - COUNTA(I$1:L$13)), "PASS WITH NOTE") -> 5 | F8: Sudah Di Test : | G8: =COUNTA(I14:INDEX(I:I, ROWS(I:I))) -> 6
B9: Test Gagal : | C9: =COUNTIF(OFFSET(I14, 0, 0, COUNTA(I:I) - COUNTA(I$1:I$13)), "FAILED") -> 1 | F9: Belum Di Test : | G9: =(G10-G8) -> 6 | H9: =(G8/G10)*100% -> 0.5 | O9: REJECTED BY QA
B10: Total Function : | C10: =COUNTA(C15:INDEX(C:C, ROWS(C:C))) -> 7 | F10: Total Test Case : | G10: =COUNTA(B14:INDEX(B:B, ROWS(B:B))) -> 12
B13: Scenario ID | C13: Function | D13: Module | E13: Test Case | F13: Test Type | G13: Expected Result | H13: Actual Result | I13: Status | J13: Test Date | K13: Tester Note | L13: Severity | M13: Link Issue | N13: Tested By | O13: Evidence
B14: a | C14: 1 | I14: pass
B15: a | C15: 1 | I15: pass
B16: a | C16: 1 | I16: pass
B17: a | C17: 1 | I17: pass
B18: a | C18: 1 | I18: pass
B19: a | C19: 1 | I19: failed
B20: a | C20: 1
B21: a | C21: 1
B22: a
B23: a
B24: a
B25: a
